Workbook

Sheet Employees
A1: employeeID | B1: fname | C1: lName | D1: position | E1: hourlypayrate | F1: hiredate | G1: FranchiseID | H1: bossID
A2: 10 | B2: June | C2: Raefel | D2: manager | E2: 26 | F2: 44446 | G2: =Franchise!A2 -> 1 | H2: NULL
A3: 11 | B3: Chris | C3: Dawson | D3: instructor | E3: 20 | F3: 44487 | G3: =Franchise!A2 -> 1 | H3: =A2 -> 10
A4: 12 | B4: Daphne | C4: Bridgerton | D4: instructor | E4: 20 | F4: 44495 | G4: =Franchise!A2 -> 1 | H4: =A2 -> 10
A5: 13 | B5: Zara | C5: Nelson | D5: instructor | E5: 19 | F5: 44869 | G5: =Franchise!A2 -> 1 | H5: =A2 -> 10
A6: 14 | B6: Mauricio | C6: Lopez | D6: instructor | E6: 19 | F6: 44902 | G6: =Franchise!A2 -> 1 | H6: =A2 -> 10
A7: 15 | B7: Jennifer | C7: Frank | D7: instructor | E7: 18 | F7: 45088 | G7: =Franchise!A2 -> 1 | H7: =A2 -> 10
A8: 16 | B8: Penelope | C8: Featherington | D8: instructor | E8: 18 | F8: 45125 | G8: =Franchise!A2 -> 1 | H8: =A2 -> 10
A9: 17 | B9: Michael | C9: Garrett | D9: frontend | E9: 17 | F9: 45012 | G9: =Franchise!A2 -> 1 | H9: =A2 -> 10
A10: 18 | B10: Brinae | C10: Bakion | D10: frontend | E10: 17 | F10: 45339 | G10: =Franchise!A2 -> 1 | H10: =A2 -> 10
A11: 19 | B11: Mercury | C11: Stardust | D11: maintenance | E11: 23 | F11: 43468 | G11: =Franchise!A2 -> 1 | H11: =A2 -> 10

Sheet Franchise
A1: franchiseID | B1: ownerID | C1: ownerfirstname | D1: ownerlastname | E1: address | F1: email | G1: phone
A2: 1 | B2: 119 | C2: Jessica | D2: Fagin | E2: 2960 E Southlake Blvd Ste 170, Southlake, TX 76092 | F2: Jessica.Fagin@gymboreeclasses.com | G2: (817) 421-9300
A3: 2 | B3: 219 | C3: Amber | D3: Glenn | E3: 1056 Town East Mall, Mesquite, TX 75150 | F3: Amber.Glenn@gymboreeclasses.com | G3: (214) 123-7845
A4: 3 | B4: 319 | C4: Nathan | D4: Chen | E4: 3450 Mt. Diablo Blvd., Lafayette, CA 94549 | F4: lafayetteca@gymboreeclasses.com | G4: (415) 604-3094
A5: 4 | B5: 419 | C5: Chester | D5: Wallace | E5: 11005 Jones Bridge Rd, Johns Creek, GA 30022 | F5: johnscreekga@gymboreeclasses.com | G5: (770) 772-4000
A6: 5 | B6: 519 | C6: Barbara | D6: Engleton | E6: 2639 Connecticut Ave. NW #133, Washington, DC 20008 | F6: wdc@gymboreeclasses.com | G6: (202) 627-2450

Sheet Timecard
A1: date | B1: employeeID | C1: starttime | D1: endtime
A2: 45458 | B2: 10
A3: 45458 | B3: 11 | C3: 0.375 | D3: 0.72916667
A4: 45458 | B4: 12 | C4: 0.375 | D4: 0.72916667
A5: 45458 | B5: 13
A6: 45458 | B6: 14
A7: 45458 | B7: 15
A8: 45458 | B8: 16
A9: 45458 | B9: 17 | C9: 0.375 | D9: 0.72916667
A10: 45458 | B10: 18
A11: 45458 | B11: 19 | C11: 0.41666667 | D11: 0.77083333
A12: 45459 | B12: 10 | C12: 0.375 | D12: 0.72916667
A13: 45459 | B13: 11
A14: 45459 | B14: 12
A15: 45459 | B15: 13 | C15: 0.375 | D15: 0.72916667
A16: 45459 | B16: 14 | C16: 0.375 | D16: 0.72916667
A17: 45459 | B17: 15 | C17: 0.375 | D17: 0.72916667
A18: 45459 | B18: 16
A19: 45459 | B19: 17
A20: 45459 | B20: 18 | C20: 0.375 | D20: 0.72916667
A21: 45459 | B21: 19 | C21: 0.41666667 | D21: 0.77083333
A22: 45460 | B22: 10 | C22: 0.33333333 | D22: 0.6875
A23: 45460 | B23: 11 | C23: 0.375 | D23: 0.72916667
A24: 45460 | B24: 12
A25: 45460 | B25: 13 | C25: 0.375 | D25: 0.72916667
A26: 45460 | B26: 14
A27: 45460 | B27: 15 | C27: 0.375 | D27: 0.72916667
A28: 45460 | B28: 16
A29: 45460 | B29: 17 | C29: 0.375 | D29: 0.72916667
A30: 45460 | B30: 18
A31: 45460 | B31: 19
A32: 45461 | B32: 10 | C32: 0.33333333 | D32: 0.6875
A33: 45461 | B33: 11
A34: 45461 | B34: 12 | C34: 0.375 | D34: 0.72916667
A35: 45461 | B35: 13
A36: 45461 | B36: 14 | C36: 0.375 | D36: 0.72916667
A37: 45461 | B37: 15
A38: 45461 | B38: 16 | C38: 0.375 | D38: 0.72916667
A39: 45461 | B39: 17
A40: 45461 | B40: 18 | C40: 0.375 | D40: 0.72916667
...

Sheet Parties
A1: partyID | B1: classname | C1: employeeID
A2: 1211 | B2: Walkers | C2: =Employees!A3 -> 11
A3: 1212 | B3: Music 1 | C3: =Employees!A4 -> 12
A4: 1213 | B4: Runners | C4: =Employees!A5 -> 13
A5: 1214 | B5: Music 2 | C5: =Employees!A6 -> 14
A6: 1215 | B6: Art 1 | C6: =Employees!A7 -> 15
A7: 1216 | B7: Explorers | C7: =Employees!A8 -> 16
A8: 1217 | B8: Babies | C8: =Employees!A3 -> 11
A9: 1218 | B9: Crawlers | C9: =Employees!A4 -> 12
A10: 1219 | B10: Preschool Steps | C10: =Employees!A5 -> 13
A11: 1220 | B11: Art 2 | C11: =Employees!A6 -> 14
A12: 1221 | B12: Walkers | C12: =Employees!A7 -> 15
A13: 1222 | B13: Music 1 | C13: =Employees!A3 -> 11
A14: 1223 | B14: Runners | C14: =Employees!A4 -> 12
A15: 1224 | B15: Music 2 | C15: =Employees!A5 -> 13
A16: 1225 | B16: Art 1 | C16: =Employees!A6 -> 14
A17: 1226 | B17: Explorers | C17: =Employees!A7 -> 15
A18: 1227 | B18: Babies | C18: =Employees!A8 -> 16
A19: 1228 | B19: Crawlers | C19: =Employees!A6 -> 14
A20: 1229 | B20: Preschool Steps | C20: =Employees!A3 -> 11
A21: 1230 | B21: Art 2 | C21: =Employees!A4 -> 12
A22: 1231 | B22: Walkers | C22: =Employees!A5 -> 13
A23: 1232 | B23: Music 1 | C23: =Employees!A6 -> 14
A24: 1233 | B24: Runners | C24: =Employees!A8 -> 16
A25: 1234 | B25: Music 2 | C25: =Employees!A6 -> 14

Sheet Customers
A1: custNo | B1: custfName | C1: custlName | D1: phoneNo | E1: cemail
A2: 1 | B2: Bruno | C2: Madrigal | D2: 555-123-4567 | E2: b.madrigal@gmail.com
A3: 2 | B3: Alice | C3: Frank | D3: 555-234-5678 | E3: a.frank@outlook.com
A4: 3 | B4: Benjamin | C4: Buttons | D4: 555-345-6789 | E4: b.buttons@hotmail.com
A5: 4 | B5: Donald | C5: Ducle | D5: 555-456-6789 | E5: d.ducle@gmail.com
A6: 5 | B6: Wendy | C6: Adams | D6: 555-567-8901 | E6: w.adams@aol.com
A7: 6 | B7: Beverly | C7: Cleary | D7: 555-678-9012 | E7: b.cleary@gmail.com
A8: 7 | B8: Raney | C8: Grohs | D8: 555-789-9123 | E8: r.cleary@gmail.com
A9: 8 | B9: Arnie | C9: Holter | D9: 555-890-1234 | E9: a.holter@outlook.com
A10: 9 | B10: Bert | C10: Penn | D10: 555-901-2345 | E10: b.penn@gmail.com
A11: 10 | B11: Ernie | C11: Disney | D11: 555-012-3456 | E11: e.disney@hotmail.com
A12: 11 | B12: Lisa | C12: Potter | D12: 555-098-7654 | E12: l.potter@gmail.com
A13: 12 | B13: Hermione | C13: Smith | D13: 555-987-6543 | E13: h.smith@gmail.com
... A25: 24 | B25: Alex | C25: Ritz | D25: 555-222-1111 | E25: a.ritz@gmail.com

Sheet Rate
A1: partyID | B1: custNo | C1: reviewdate | D1: rating
A2: 1211 | B2: 1 | C2: 45466 | D2: 4
A3: 1212 | B3: 2 | C3: 45466 | D3: 5
A4: 1213 | B4: 3 | C4: 45467 | D4: 1
A5: 1214 | B5: 4 | C5: 45467 | D5: 3
A6: 1215 | B6: 5 | C6: 45468 | D6: 4
A7: 1216 | B7: 6 | C7: 45469 | D7: 5
A8: 1217 | B8: 7 | C8: 45469 | D8: 3
A9: 1218 | B9: 8 | C9: 45470 | D9: 4
A10: 1219 | B10: 9 | C10: 45470 | D10: 4
A11: 1220 | B11: 10 | C11: 45466 | D11: 3
A12: 1221 | B12: 11 | C12: 45467 | D12: 5
A13: 1222 | B13: 12 | C13: 45468 | D13: 2
... A25: 1234 | B25: 24 | C25: 45467 | D25: 4

Sheet Bookings
A1: bookingID | B1: bookingdate | C1: custNo | D1: confirmationNo
A2: 121124 | B2: 45458 | C2: 1 | D2: 1211241
A3: 121224 | B3: 45458 | C3: 2 | D3: 1212241
A4: 121324 | B4: 45459 | C4: 3 | D4: 1213241
A5: 121424 | B5: 45459 | C5: 4 | D5: 1214241
A6: 121524 | B6: 45459 | C6: 5 | D6: 1215241
A7: 121624 | B7: 45460 | C7: 6 | D7: 1216241
A8: 121625 | B8: 45460 | C8: 7 | D8: 1216242
A9: 121626 | B9: 45460 | C9: 8 | D9: 1216243
A10: 121627 | B10: 45461 | C10: 9 | D10: 1216244
A11: 121628 | B11: 45461 | C11: 10 | D11: 1216245
A12: 121629 | B12: 45461 | C12: 11 | D12: 1216246
A13: 121630 | B13: 45462 | C13: 12 | D13: 1216247
... A25: 121642 | B25: 45465 | C25: 24 | D25: 1216259

Sheet Payments
A1: confirmationNo | B1: amount | C1: paymentType | D1: datetime | E1: status
A2: 1211241 | B2: 449 | C2: debit | D2: 6/1/2024 6:00 PM CST | E2: completed
A3: 1212241 | B3: 499 | C3: credit | D3: 6/4/2024 3:00 PM CST | E3: completed
A4: 1213241 | B4: 449 | C4: cash | D4: 6/6/2024 8:00 AM CST | E4: refunded
A5: 1214241 | B5: 499 | C5: check | D5: 6/12/2024 11:00 AM CST | E5: completed
A6: 1215241 | B6: 449 | C6: credit | D6: 6/13/2024 7:00 PM CST | E6: completed
A7: 1216241 | B7: 499 | C7: debit | D7: 6/13/2024 11:00 AM CST | E7: completed
A8: 1216242 | B8: 449 | C8: debit | D8: 6/2/2024 7:00 AM CST | E8: completed
A9: 1216243 | B9: 499 | C9: credit | D9: 6/12/2024 11:00 AM CST | E9: completed
A10: 1216244 | B10: 449 | C10: cash | D10: 6/4/2024 3:00 PM CST | E10: completed
A11: 1216245 | B11: 499 | C11: check | D11: 6/13/2024 11:00 AM CST | E11: completed
A12: 1216246 | B12: 449 | C12: credit | D12: 6/12/2024 11:00 AM CST | E12: completed
A13: 1216247 | B13: 499 | C13: debit | D13: 6/2/2024 7:00 AM CST | E13: completed
... A25: 1216259 | B25: 499 | C25: debit | D25: 6/2/2024 7:00 AM CST | E25: completed
